Workbook

Sheet startlisteklasser
A1: 45935.417 | B1: 43 | C1: Skrittklass Lag grund och kür klass 15, 16 | D1: 700 | E1: 999 | F1: P V - Skrittklass lag typ 1 | G1: 1
B2: 43 | C2: Skrittklass Lag grund och kür klass 15, 16 | D2: 700 | E2: 999 | F2: P V - Skrittklass lag typ 1 | G2: 2
B3: 43 | C3: Skrittklass Lag grund och kür klass 15, 16 | D3: 769951 | E3: 15 | F3: Skrittklass, lag typ 1 | G3: 1
B4: 43 | C4: Skrittklass Lag grund och kür klass 15, 16 | D4: 769951 | E4: 15 | F4: Skrittklass, lag typ 1 | G4: 2
B5: 43 | C5: Skrittklass Lag grund och kür klass 15, 16 | D5: 769952 | E5: 16 | F5: Skrittklass, lag typ 2 | G5: 1
B6: 43 | C6: Skrittklass Lag grund och kür klass 15, 16 | D6: 769952 | E6: 16 | F6: Skrittklass, lag typ 2 | G6: 2
B7: 52 | C7: Mixklass klass 12 | D7: 769949 | E7: 13 | F7: Mixklass 0* | G7: 1
B8: 52 | C8: Mixklass klass 12 | D8: 769949 | E8: 13 | F8: Mixklass 0* | G8: 2
B9: 18 | C9: Svår klass lag seniorer klass 1 – Grund | D9: 769936 | E9: 1 | F9: Svår klass, Seniorlag | G9: 1
B10: 1 | C10: Svår klass individuella klass 3, 4, 5, 6, 7, 8 – Grund/tekn kür | D10: 769939 | E10: 3 | F10: Individuell senior 3* | G10: 1
B11: 1 | C11: Svår klass individuella klass 3, 4, 5, 6, 7, 8 – Grund/tekn kür | D11: 769939 | E11: 3 | F11: Individuell senior 3* | G11: 2
B12: 1 | C12: Svår klass individuella klass 3, 4, 5, 6, 7, 8 – Grund/tekn kür | D12: 769940 | E12: 4 | F12: Individuell senior 2* | G12: 1
B13: 1 | C13: Svår klass individuella klass 3, 4, 5, 6, 7, 8 – Grund/tekn kür | D13: 769941 | E13: 5 | F13: Individuell senior 1* | G13: 1
... B30: 2 | C30: Svår klass individuella klass 3, 4, 5, 6, 7, 8 – Kür | D30: 769945 | E30: 9 | F30: Individuell minior 1* | G30: 2

Sheet ekipage
A1: 700 | B1: 999 | C1: P V - Skrittklass lag typ 1 | D1: 57688 | E1: Erika Hansen | F1: 339009 | G1: Odinn | J1: 223 | K1: Föreningen Uppsala Voltige | M1: Indus | N1: 90 | O1: Elvira Androos | P1: 91 | Q1: Selma Ouled El Housseine | R1: 92 | S1: Tilda Månsson | T1: 93 | U1: Signe Säfström | V1: 94 | W1: Mila Thulin | X1: 95 | Y1: Felicia Söderman | Z1: 96 | AA1: Hedvig Säfström
A2: 769936 | B2: 1 | C2: Svår klass, Seniorlag | D2: 68838 | E2: Marie Johansson | F2: 308300 | G2: Gladiator VDH | J2: 1330 | K2: Sala Voltige och Hästsportförening | M2: Athena | N2: 164696 | O2: Amanda Lundén Pliscovaz | P2: 195030 | Q2: Elly Malta | R2: 203320 | S2: Malin Folgerö | T2: 155903 | U2: Julia Kristensson | V2: 164698 | W2: Ellen Eriksson | X2: 140351 | Y2: Meja Högberg
A3: 769943 | B3: 7 | C3: Individuell junior 2* | D3: 40552 | E3: Annelie Lundgren | F3: 328352 | G3: Iniesta | J3: 869 | K3: Hamre Ridklubb | L3: Så långt som möjligt mellan Iniesta och Klondike | N3: 145535 | O3: Agnes Kumm
A4: 769943 | B4: 7 | C4: Individuell junior 2* | D4: 65038 | E4: Christina Müller | F4: 312598 | G4: Diamond | J4: 223 | K4: Föreningen Uppsala Voltige | N4: 101580 | O4: Linnea Jennische
A5: 769940 | B5: 4 | C5: Individuell senior 2* | D5: 44766 | E5: Andrea Raud | F5: 293254 | G5: Cortesch (SWB) | J5: 223 | K5: Föreningen Uppsala Voltige | N5: 124472 | O5: Ebba Holmberg
A6: 769939 | B6: 3 | C6: Individuell senior 3* | D6: 39162 | E6: Sofia Fågelsbo | F6: 342703 | G6: Serenade | J6: 1330 | K6: Sala Voltige och Hästsportförening | L6: Grund och teknisk i olika inspring. Ordning Fanny,Ebba,Emilia | N6: 51513 | O6: Fanny Eklund
A7: 769943 | B7: 7 | C7: Individuell junior 2* | D7: 39162 | E7: Sofia Fågelsbo | F7: 342703 | G7: Serenade | J7: 223 | K7: Föreningen Uppsala Voltige | N7: 155140 | O7: Ebba Wallqvist
A8: 769943 | B8: 7 | C8: Individuell junior 2* | D8: 95073 | E8: Angelica Thunman | F8: 279357 | G8: Halving | J8: 1198 | K8: Fortuna Voltigeförening | N8: 97 | O8: Sofia Ekström
A9: 769940 | B9: 4 | C9: Individuell senior 2* | D9: 44766 | E9: Andrea Raud | F9: 123 | G9: Cortesch_(SWB) | J9: 223 | K9: Föreningen Uppsala Voltige | N9: 160950 | O9: Thea Lundell
A10: 769939 | B10: 3 | C10: Individuell senior 3* | D10: 39162 | E10: Sofia Fågelsbo | F10: 342703 | G10: Serenade | J10: 1330 | K10: Sala Voltige och Hästsportförening | L10: Startordning:, 1. Fanny Eklund , 2. Ebba Wallqvist , 3. Emilia Bäck , , Grund och tekniskt i olika inspring | N10: 99453 | O10: Emilia Bäck
A11: 769940 | B11: 4 | C11: Individuell senior 2* | D11: 40552 | E11: Annelie Lundgren | F11: 354215 | G11: Crisanto S | J11: 869 | K11: Hamre Ridklubb | N11: 106236 | O11: My Lindström
A12: 769941 | B12: 5 | C12: Individuell senior 1* | D12: 39667 | E12: Linda Viklund | F12: 342894 | G12: Charlz (SWB) | J12: 986 | K12: Timrå Hästsportförening | N12: 134303 | O12: Henny Lind
A13: 769940 | B13: 4 | C13: Individuell senior 2* | D13: 36847 | E13: Linda Jenvall | F13: 280330 | G13: Calouha | J13: 223 | K13: Föreningen Uppsala Voltige | N13: 101407 | O13: Tindra Öberg
A14: 769940 | B14: 4 | C14: Individuell senior 2* | D14: 36847 | E14: Linda Jenvall | F14: 280330 | G14: Calouha | J14: 223 | K14: Föreningen Uppsala Voltige | N14: 119893 | O14: Novalie Wall
A15: 769943 | B15: 7 | C15: Individuell junior 2* | D15: 24976 | E15: Cecilia Rasmussen | F15: 316201 | G15: Farrakech (SWB) | J15: 1330 | K15: Sala Voltige och Hästsportförening | N15: 155915 | O15: Isabelle Rasmussen
A16: 769943 | B16: 7 | C16: Individuell junior 2* | D16: 24976 | E16: Cecilia Rasmussen | F16: 316201 | G16: Farrakech (SWB) | J16: 223 | K16: Föreningen Uppsala Voltige | L16: Elda tävlar för Uppsala Voltige | N16: 155892 | O16: Elda Lindberg
A17: 769943 | B17: 7 | C17: Individuell junior 2* | D17: 65038 | E17: Christina Müller | F17: 321025 | G17: Castell (SWB) | J17: 223 | K17: Föreningen Uppsala Voltige | N17: 164010 | O17: Tuva Wipemo
A18: 769943 | B18: 7 | C18: Individuell junior 2* | D18: 44766 | E18: Andrea Raud | F18: 293254 | G18: Cortesch (SWB) | J18: 223 | K18: Föreningen Uppsala Voltige | N18: 163943 | O18: Wilma Ericson Flack
A19: 769943 | B19: 7 | C19: Individuell junior 2* | D19: 65038 | E19: Christina Müller | F19: 321025 | G19: Castell (SWB) | J19: 223 | K19: Föreningen Uppsala Voltige | N19: 182163 | O19: Alicia Ramberg
A20: 769943 | B20: 7 | C20: Individuell junior 2* | D20: 95073 | E20: Angelica Thunman | F20: 279357 | G20: Halving | J20: 1198 | K20: Fortuna Voltigeförening | N20: 129688 | O20: Ella Eriksson
A21: 769943 | B21: 7 | C21: Individuell junior 2* | D21: 40552 | E21: Annelie Lundgren | F21: 354215 | G21: Crisanto S | J21: 869 | K21: Hamre Ridklubb | N21: 134608 | O21: Linnea Pedersen
A22: 769944 | B22: 8 | C22: Individuell junior 1* | D22: 39667 | E22: Linda Viklund | F22: 342894 | G22: Charlz (SWB) | J22: 986 | K22: Timrå Hästsportförening | N22: 155124 | O22: Agnes Viklund
A23: 769944 | B23: 8 | C23: Individuell junior 1* | D23: 39667 | E23: Linda Viklund | F23: 342894 | G23: Charlz (SWB) | J23: 986 | K23: Timrå Hästsportförening | N23: 200328 | O23: Olivia Nyberg
A24: 769945 | B24: 9 | C24: Individuell minior 1* | D24: 44766 | E24: Andrea Raud | F24: 123 | G24: Cortesch_(SWB) | J24: 223 | K24: Föreningen Uppsala Voltige | L24: Missade att fylla i ”sena ändringar” och önskar det som tillägg. | N24: 190842 | O24: Vera Bjarnemo
A25: 769945 | B25: 9 | C25: Individuell minior 1* | D25: 95073 | E25: Angelica Thunman | F25: 279357 | G25: Halving | J25: 1198 | K25: Fortuna Voltigeförening | N25: 178209 | O25: Selma Åkesson
A26: 769943 | B26: 7 | C26: Individuell junior 2* | D26: 40552 | E26: Annelie Lundgren | F26: 330385 | G26: Klondike | J26: 869 | K26: Hamre Ridklubb | L26: Så långt som möjligt mellan Iniesta och Klondike. , Klondike är helt ny och detta är hans första tävling. | N26: 98 | O26: Agnes Kumm
A27: 769951 | B27: 15 | C27: Skrittklass, lag typ 1 | D27: 36847 | E27: Linda Jenvall | F27: 280330 | G27: Calouha | J27: 223 | K27: Föreningen Uppsala Voltige | L27: Uppsala Team Andromeda, , Startordning: Ariah, Elna, Nelia, Alma, Sigrid. | M27: Andromeda Svart | N27: 195029 | O27: Ariah Fischer | P27: 195002 | Q27: Elna Stidelius | R27: 194941 | S27: Nelia Palmius | T27: 202342 | U27: Alma Bjarnemo | V27: 195003 | W27: Sigrid Stidelius
A28: 769952 | B28: 16 | C28: Skrittklass, lag typ 2 | D28: 180813 | E28: Jenny Rova | F28: 328098 | G28: Turbic Boy (SWB) | J28: 1330 | K28: Sala Voltige och Hästsportförening | L28: Team Eros , Startordning:, 1. Milou Hallgren, 2. Meja Bergqvist, 3. Moa Jansson, 4. Julia Elvnäs , 5. Noelia Vega Santibanez | M28: Eros | N28: 203576 | O28: Milou Hallgren | P28: 190728 | Q28: Meja Bergqvist | R28: 203579 | S28: Moa Jansson | T28: 206216 | U28: Julia Elvnäs | V28: 204013 | W28: Noelia Vega Santibanez
A29: 769951 | B29: 15 | C29: Skrittklass, lag typ 1 | D29: 36847 | E29: Linda Jenvall | F29: 280330 | G29: Calouha | J29: 223 | K29: Föreningen Uppsala Voltige | L29: Uppsala Team Andromeda Blå, , Det andra laget kan heta Andromeda Svart | M29: Andromeda Blå | N29: 202327 | O29: Lovis Berg | P29: 202520 | Q29: Nikki Gladh | R29: 205893 | S29: Melina Vesterholm | T29: 194944 | U29: Linnéa Lif
A30: 769949 | B30: 13 | C30: Mixklass 0* | D30: 49704 | E30: JoAnna Bäck | F30: 124 | G30: Orlando Van't Merodehof | J30: 1330 | K30: Sala Voltige och Hästsportförening | L30: Team Atlas, Startordning, 1 Mollie strandberg , 2 Nova Lindgren , 3 Enzo folgerö , 4 Mira Bergqvist, 5 Louise Hörnstedt, 6 Svea Torssander | M30: Atlas | N30: 206123 | O30: Enzo Folgerö | P30: 171512 | Q30: Mira Bergqvist | R30: 181877 | S30: Mollie Strandberg | T30: 201304 | U30: Louise Hörnstedt | V30: 186888 | W30: Svea Torssander | X30: 200754 | Y30: Nova Lindgren
A31: 769953 | B31: 17 | C31: Lättklass, Individuell | D31: 65539 | E31: Connie Rebane | F31: 262992 | G31: Hembys Bellman | J31: 869 | K31: Hamre Ridklubb | L31: Mia kumm linför, connie värmer upp, | N31: 195035 | O31: Haylie Rebane
A32: 769953 | B32: 17 | C32: Lättklass, Individuell | D32: 34557 | E32: Maria Kumm | F32: 262992 | G32: Hembys Bellman | J32: 869 | K32: Hamre Ridklubb | N32: 195019 | O32: Ebba Fasthamre
A33: 769953 | B33: 17 | C33: Lättklass, Individuell | D33: 96828 | E33: Anna-Tuva Andersson | F33: 334748 | G33: Silver | J33: 1330 | K33: Sala Voltige och Hästsportförening | N33: 206243 | O33: Elsa Söderberg
A34: 769953 | B34: 17 | C34: Lättklass, Individuell | D34: 180813 | E34: Jenny Rova | F34: 328098 | G34: Turbic Boy (SWB) | J34: 1330 | K34: Sala Voltige och Hästsportförening | N34: 29744 | O34: Denice Sundberg
A35: 769953 | B35: 17 | C35: Lättklass, Individuell | D35: 180813 | E35: Jenny Rova | F35: 328098 | G35: Turbic Boy (SWB) | J35: 986 | K35: Timrå Hästsportförening | L35: Höger varv | N35: 169428 | O35: Cecilia Viklund
A36: 769953 | B36: 17 | C36: Lättklass, Individuell | D36: 180813 | E36: Jenny Rova | F36: 328098 | G36: Turbic Boy (SWB) | J36: 986 | K36: Timrå Hästsportförening | L36: Höger varv | N36: 186749 | O36: Tyra Karlsson
A37: 769953 | B37: 17 | C37: Lättklass, Individuell | D37: 24976 | E37: Cecilia Rasmussen | F37: 316201 | G37: Farrakech (SWB) | J37: 1330 | K37: Sala Voltige och Hästsportförening | N37: 163633 | O37: Julia Ekblom
A38: 769953 | B38: 17 | C38: Lättklass, Individuell | D38: 49704 | E38: JoAnna Bäck | F38: 124 | G38: Orlando Van't Merodehof | J38: 1330 | K38: Sala Voltige och Hästsportförening | N38: 181877 | O38: Mollie Strandberg
A39: 769954 | B39: 18 | C39: Skrittklass, individuell | D39: 68838 | E39: Marie Johansson | F39: 308300 | G39: Gladiator VDH | J39: 223 | K39: Föreningen Uppsala Voltige | L39: Tävlar för Uppsala Voltige | N39: 202327 | O39: Lovis Berg
A40: 769954 | B40: 18 | C40: Skrittklass, individuell | D40: 34557 | E40: Maria Kumm | F40: 349212 | G40: Zara | H40: 262992 | I40: Hembys Bellman | J40: 869 | K40: Hamre Ridklubb | N40: 172842 | O40: Ronja Berggren
...

Sheet klasser
A1: 769936 | B1: 1 | C1: Svår klass, Seniorlag | D1: 1
A2: 769937 | B2: 2 | C2: Svår klass, Juniorlag | D2: 13
A3: 769939 | B3: 3 | C3: Individuell senior 3* | D3: 25
A4: 769940 | B4: 4 | C4: Individuell senior 2* | D4: 1076
A5: 769941 | B5: 5 | C5: Individuell senior 1* | D5: 1077
A6: 769942 | B6: 6 | C6: Individuell young vaulter | D6: 1060
A7: 769943 | B7: 7 | C7: Individuell junior 2* | D7: 33 | E7: 33 3 domare 34 för 4 domare
A8: 769944 | B8: 8 | C8: Individuell junior 1* | D8: 1078
A9: 769945 | B9: 9 | C9: Individuell minior 1* | D9: 37
A10: 769946 | B10: 10 | C10: Pas de deux
A11: 769947 | B11: 11 | C11: Mellanklass, lag
A12: 769948 | B12: 12 | C12: Mixklass 1* | D12: 1054
A13: 769949 | B13: 13 | C13: Mixklass 0* | D13: 50
A14: 769950 | B14: 14 | C14: Lättklass, lag | D14: 1095
A15: 769951 | B15: 15 | C15: Skrittklass, lag typ 1 | D15: 44 | E15: 44 2 domare | F15: 51 3 domare
A16: 769952 | B16: 16 | C16: Skrittklass, lag typ 2 | D16: 1058 | E16: 1058 2 domare | F16: 1059 3 domare
A17: 769953 | B17: 17 | C17: Lättklass, Individuell | D17: 48 | E17: 43 2 domare
A18: 769954 | B18: 18 | C18: Skrittklass, individuell | D18: 49 | E18: 45 2 domare
A19: 769955 | B19: 19 | C19: Skrittklass, pas de deux | D19: 1056 | E19: 1055 2 domare
A20: 700 | B20: 999 | C20: P V - Skrittklass lag typ 1 | D20: 52 | E20: 52 = mer än 6 deltagare

Sheet linförare
A1: 68838 | B1: Marie Johansson
A2: 39162 | B2: Sofia Fågelsbo
A3: 36847 | B3: Linda Jenvall
A4: 44766 | B4: Andrea Raud
A5: 40552 | B5: Annelie Lundgren
A6: 39667 | B6: Linda Viklund
A7: 24976 | B7: Cecilia Rasmussen
A8: 65038 | B8: Christina Müller
A9: 95073 | B9: Angelica Thunman
A10: 49704 | B10: JoAnna Bäck
A11: 180813 | B11: Jenny Rova
A12: 65539 | B12: Connie Rebane
... A15: 57688 | B15: Erika Hansen

Sheet reservhästar
A1: 0 | B1: -
A2: 262992 | B2: Hembys Bellman

Sheet hästar
A1: 308300 | B1: Gladiator VDH
A2: 342703 | B2: Serenade
A3: 280330 | B3: Calouha
A4: 293254 | B4: Cortesch (SWB)
A5: 354215 | B5: Crisanto S
A6: 342894 | B6: Charlz (SWB)
A7: 316201 | B7: Farrakech (SWB)
A8: 312598 | B8: Diamond
A9: 321025 | B9: Castell (SWB)
A10: 328352 | B10: Iniesta
A11: 279357 | B11: Halving
A12: 330385 | B12: Klondike
... A20: 124 | B20: Orlando Van't Merodehof

Sheet klubbar
A1: 1330 | B1: Sala Voltige och Hästsportförening | C1: SE
A2: 233 | B2: Lagga Fältrittklubb | C2: SE
A3: 223 | B3: Föreningen Uppsala Voltige | C3: SE
A4: 869 | B4: Hamre Ridklubb | C4: SE
A5: 986 | B5: Timrå Hästsportförening | C5: SE
A6: 1198 | B6: Fortuna Voltigeförening | C6: SE
A7: 867 | B7: Föreningen Skästa Ridcenter | C7: SE

Sheet voltigörer
A2: 164696 | B2: Amanda Lundén Pliscovaz | I2: {=IF(K2="Visa klasser",IFERROR(INDEX(ekipage!B:B,MATCH(1,(ekipage!O:O=A2)*(ISNUMBER(ekipage!Q:Q)=FALSE),0)),""),"")} | J2: {=IF(K2="Visa klasser",IFERROR(INDEX(ekipage!C:C, MATCH(1, (ekipage!O:O = A2) * (ISNUMBER(ekipage!Q:Q) = FALSE), 0)), "Ej individuell"),"Visar ej klasser")} -> Visar ej klasser | K2: Visa klasser ej
A3: 195030 | B3: Elly Malta | I3: {=IF(K3="Visa klasser",IFERROR(INDEX(ekipage!B:B,MATCH(1,(ekipage!O:O=A3)*(ISNUMBER(ekipage!Q:Q)=FALSE),0)),""),"")} | J3: {=IF(K3="Visa klasser",IFERROR(INDEX(ekipage!C:C, MATCH(1, (ekipage!O:O = A3) * (ISNUMBER(ekipage!Q:Q) = FALSE), 0)), "Ej individuell"),"Visar ej klasser")} -> Visar ej klasser | K3: Visa klasser ej
A4: 203320 | B4: Malin Folgerö | I4: {=IF(K4="Visa klasser",IFERROR(INDEX(ekipage!B:B,MATCH(1,(ekipage!O:O=A4)*(ISNUMBER(ekipage!Q:Q)=FALSE),0)),""),"")} | J4: {=IF(K4="Visa klasser",IFERROR(INDEX(ekipage!C:C, MATCH(1, (ekipage!O:O = A4) * (ISNUMBER(ekipage!Q:Q) = FALSE), 0)), "Ej individuell"),"Visar ej klasser")} -> Visar ej klasser | K4: Visa klasser ej
A5: 155903 | B5: Julia Kristensson | I5: {=IF(K5="Visa klasser",IFERROR(INDEX(ekipage!B:B,MATCH(1,(ekipage!O:O=A5)*(ISNUMBER(ekipage!Q:Q)=FALSE),0)),""),"")} | J5: {=IF(K5="Visa klasser",IFERROR(INDEX(ekipage!C:C, MATCH(1, (ekipage!O:O = A5) * (ISNUMBER(ekipage!Q:Q) = FALSE), 0)), "Ej individuell"),"Visar ej klasser")} -> Visar ej klasser | K5: Visa klasser ej
A6: 164698 | B6: Ellen Eriksson | I6: {=IF(K6="Visa klasser",IFERROR(INDEX(ekipage!B:B,MATCH(1,(ekipage!O:O=A6)*(ISNUMBER(ekipage!Q:Q)=FALSE),0)),""),"")} | J6: {=IF(K6="Visa klasser",IFERROR(INDEX(ekipage!C:C, MATCH(1, (ekipage!O:O = A6) * (ISNUMBER(ekipage!Q:Q) = FALSE), 0)), "Ej individuell"),"Visar ej klasser")} -> Visar ej klasser | K6: Visa klasser ej
A7: 140351 | B7: Meja Högberg | I7: {=IF(K7="Visa klasser",IFERROR(INDEX(ekipage!B:B,MATCH(1,(ekipage!O:O=A7)*(ISNUMBER(ekipage!Q:Q)=FALSE),0)),""),"")} | J7: {=IF(K7="Visa klasser",IFERROR(INDEX(ekipage!C:C, MATCH(1, (ekipage!O:O = A7) * (ISNUMBER(ekipage!Q:Q) = FALSE), 0)), "Ej individuell"),"Visar ej klasser")} -> Visar ej klasser | K7: Visa klasser ej
A8: 99453 | B8: Emilia Bäck | I8: {=IF(K8="Visa klasser",IFERROR(INDEX(ekipage!B:B,MATCH(1,(ekipage!O:O=A8)*(ISNUMBER(ekipage!Q:Q)=FALSE),0)),""),"")} | J8: {=IF(K8="Visa klasser",IFERROR(INDEX(ekipage!C:C, MATCH(1, (ekipage!O:O = A8) * (ISNUMBER(ekipage!Q:Q) = FALSE), 0)), "Ej individuell"),"Visar ej klasser")} -> Visar ej klasser | K8: Visa klasser ej
A9: 51513 | B9: Fanny Eklund | I9: {=IF(K9="Visa klasser",IFERROR(INDEX(ekipage!B:B,MATCH(1,(ekipage!O:O=A9)*(ISNUMBER(ekipage!Q:Q)=FALSE),0)),""),"")} | J9: {=IF(K9="Visa klasser",IFERROR(INDEX(ekipage!C:C, MATCH(1, (ekipage!O:O = A9) * (ISNUMBER(ekipage!Q:Q) = FALSE), 0)), "Ej individuell"),"Visar ej klasser")} -> Visar ej klasser | K9: Visa klasser ej
A10: 101407 | B10: Tindra Öberg | I10: {=IF(K10="Visa klasser",IFERROR(INDEX(ekipage!B:B,MATCH(1,(ekipage!O:O=A10)*(ISNUMBER(ekipage!Q:Q)=FALSE),0)),""),"")} | J10: {=IF(K10="Visa klasser",IFERROR(INDEX(ekipage!C:C, MATCH(1, (ekipage!O:O = A10) * (ISNUMBER(ekipage!Q:Q) = FALSE), 0)), "Ej individuell"),"Visar ej klasser")} -> Visar ej klasser | K10: Visa klasser ej
A11: 119893 | B11: Novalie Wall | I11: {=IF(K11="Visa klasser",IFERROR(INDEX(ekipage!B:B,MATCH(1,(ekipage!O:O=A11)*(ISNUMBER(ekipage!Q:Q)=FALSE),0)),""),"")} | J11: {=IF(K11="Visa klasser",IFERROR(INDEX(ekipage!C:C, MATCH(1, (ekipage!O:O = A11) * (ISNUMBER(ekipage!Q:Q) = FALSE), 0)), "Ej individuell"),"Visar ej klasser")} -> Visar ej klasser | K11: Visa klasser ej
A12: 124472 | B12: Ebba Holmberg | I12: {=IF(K12="Visa klasser",IFERROR(INDEX(ekipage!B:B,MATCH(1,(ekipage!O:O=A12)*(ISNUMBER(ekipage!Q:Q)=FALSE),0)),""),"")} | J12: {=IF(K12="Visa klasser",IFERROR(INDEX(ekipage!C:C, MATCH(1, (ekipage!O:O = A12) * (ISNUMBER(ekipage!Q:Q) = FALSE), 0)), "Ej individuell"),"Visar ej klasser")} -> Visar ej klasser | K12: Visa klasser ej
A13: 160950 | B13: Thea Lundell | I13: {=IF(K13="Visa klasser",IFERROR(INDEX(ekipage!B:B,MATCH(1,(ekipage!O:O=A13)*(ISNUMBER(ekipage!Q:Q)=FALSE),0)),""),"")} | J13: {=IF(K13="Visa klasser",IFERROR(INDEX(ekipage!C:C, MATCH(1, (ekipage!O:O = A13) * (ISNUMBER(ekipage!Q:Q) = FALSE), 0)), "Ej individuell"),"Visar ej klasser")} -> Visar ej klasser | K13: Visa klasser ej
... A70: 98 | B70: Agnes Kumm | I70: {=IF(K70="Visa klasser",IFERROR(INDEX(ekipage!B:B,MATCH(1,(ekipage!O:O=A70)*(ISNUMBER(ekipage!Q:Q)=FALSE),0)),""),"")} | J70: {=IF(K70="Visa klasser",IFERROR(INDEX(ekipage!C:C, MATCH(1, (ekipage!O:O = A70) * (ISNUMBER(ekipage!Q:Q) = FALSE), 0)), "Ej individuell"),"Visar ej klasser")} -> Visar ej klasser | K70: Visa klasser ej
I71: {=IF(K71="Visa klasser",IFERROR(INDEX(ekipage!B:B,MATCH(1,(ekipage!O:O=A71)*(ISNUMBER(ekipage!Q:Q)=FALSE),0)),""),"")} | J71: {=IF(K71="Visa klasser",IFERROR(INDEX(ekipage!C:C, MATCH(1, (ekipage!O:O = A71) * (ISNUMBER(ekipage!Q:Q) = FALSE), 0)), "Ej individuell"),"Visar ej klasser")} -> Visar ej klasser | K71: Visa klasser ej
I72: {=IF(K72="Visa klasser",IFERROR(INDEX(ekipage!B:B,MATCH(1,(ekipage!O:O=A72)*(ISNUMBER(ekipage!Q:Q)=FALSE),0)),""),"")} | J72: {=IF(K72="Visa klasser",IFERROR(INDEX(ekipage!C:C, MATCH(1, (ekipage!O:O = A72) * (ISNUMBER(ekipage!Q:Q) = FALSE), 0)), "Ej individuell"),"Visar ej klasser")} -> Visar ej klasser | K72: Visa klasser ej
I73: {=IF(K73="Visa klasser",IFERROR(INDEX(ekipage!B:B,MATCH(1,(ekipage!O:O=A73)*(ISNUMBER(ekipage!Q:Q)=FALSE),0)),""),"")} | J73: {=IF(K73="Visa klasser",IFERROR(INDEX(ekipage!C:C, MATCH(1, (ekipage!O:O = A73) * (ISNUMBER(ekipage!Q:Q) = FALSE), 0)), "Ej individuell"),"Visar ej klasser")} -> Visar ej klasser | K73: Visa klasser ej
I74: {=IF(K74="Visa klasser",IFERROR(INDEX(ekipage!B:B,MATCH(1,(ekipage!O:O=A74)*(ISNUMBER(ekipage!Q:Q)=FALSE),0)),""),"")} | J74: {=IF(K74="Visa klasser",IFERROR(INDEX(ekipage!C:C, MATCH(1, (ekipage!O:O = A74) * (ISNUMBER(ekipage!Q:Q) = FALSE), 0)), "Ej individuell"),"Visar ej klasser")} -> Visar ej klasser | K74: Visa klasser ej
I75: {=IF(K75="Visa klasser",IFERROR(INDEX(ekipage!B:B,MATCH(1,(ekipage!O:O=A75)*(ISNUMBER(ekipage!Q:Q)=FALSE),0)),""),"")} | J75: {=IF(K75="Visa klasser",IFERROR(INDEX(ekipage!C:C, MATCH(1, (ekipage!O:O = A75) * (ISNUMBER(ekipage!Q:Q) = FALSE), 0)), "Ej individuell"),"Visar ej klasser")} -> Visar ej klasser | K75: Visa klasser ej
I76: {=IF(K76="Visa klasser",IFERROR(INDEX(ekipage!B:B,MATCH(1,(ekipage!O:O=A76)*(ISNUMBER(ekipage!Q:Q)=FALSE),0)),""),"")} | J76: {=IF(K76="Visa klasser",IFERROR(INDEX(ekipage!C:C, MATCH(1, (ekipage!O:O = A76) * (ISNUMBER(ekipage!Q:Q) = FALSE), 0)), "Ej individuell"),"Visar ej klasser")} -> Visar ej klasser | K76: Visa klasser ej
I77: {=IF(K77="Visa klasser",IFERROR(INDEX(ekipage!B:B,MATCH(1,(ekipage!O:O=A77)*(ISNUMBER(ekipage!Q:Q)=FALSE),0)),""),"")} | J77: {=IF(K77="Visa klasser",IFERROR(INDEX(ekipage!C:C, MATCH(1, (ekipage!O:O = A77) * (ISNUMBER(ekipage!Q:Q) = FALSE), 0)), "Ej individuell"),"Visar ej klasser")} -> Visar ej klasser | K77: Visa klasser ej
I78: {=IF(K78="Visa klasser",IFERROR(INDEX(ekipage!B:B,MATCH(1,(ekipage!O:O=A78)*(ISNUMBER(ekipage!Q:Q)=FALSE),0)),""),"")} | J78: {=IF(K78="Visa klasser",IFERROR(INDEX(ekipage!C:C, MATCH(1, (ekipage!O:O = A78) * (ISNUMBER(ekipage!Q:Q) = FALSE), 0)), "Ej individuell"),"Visar ej klasser")} -> Visar ej klasser | K78: Visa klasser ej
I79: {=IF(K79="Visa klasser",IFERROR(INDEX(ekipage!B:B,MATCH(1,(ekipage!O:O=A79)*(ISNUMBER(ekipage!Q:Q)=FALSE),0)),""),"")} | J79: {=IF(K79="Visa klasser",IFERROR(INDEX(ekipage!C:C, MATCH(1, (ekipage!O:O = A79) * (ISNUMBER(ekipage!Q:Q) = FALSE), 0)), "Ej individuell"),"Visar ej klasser")} -> Visar ej klasser | K79: Visa klasser ej
I80: {=IF(K80="Visa klasser",IFERROR(INDEX(ekipage!B:B,MATCH(1,(ekipage!O:O=A80)*(ISNUMBER(ekipage!Q:Q)=FALSE),0)),""),"")} | J80: {=IF(K80="Visa klasser",IFERROR(INDEX(ekipage!C:C, MATCH(1, (ekipage!O:O = A80) * (ISNUMBER(ekipage!Q:Q) = FALSE), 0)), "Ej individuell"),"Visar ej klasser")} -> Visar ej klasser | K80: Visa klasser ej
I81: {=IF(K81="Visa klasser",IFERROR(INDEX(ekipage!B:B,MATCH(1,(ekipage!O:O=A81)*(ISNUMBER(ekipage!Q:Q)=FALSE),0)),""),"")} | J81: {=IF(K81="Visa klasser",IFERROR(INDEX(ekipage!C:C, MATCH(1, (ekipage!O:O = A81) * (ISNUMBER(ekipage!Q:Q) = FALSE), 0)), "Ej individuell"),"Visar ej klasser")} -> Visar ej klasser | K81: Visa klasser ej
I82: {=IF(K82="Visa klasser",IFERROR(INDEX(ekipage!B:B,MATCH(1,(ekipage!O:O=A82)*(ISNUMBER(ekipage!Q:Q)=FALSE),0)),""),"")} | J82: {=IF(K82="Visa klasser",IFERROR(INDEX(ekipage!C:C, MATCH(1, (ekipage!O:O = A82) * (ISNUMBER(ekipage!Q:Q) = FALSE), 0)), "Ej individuell"),"Visar ej klasser")} -> Visar ej klasser | K82: Visa klasser ej
... I124: {=IF(K124="Visa klasser",IFERROR(INDEX(ekipage!B:B,MATCH(1,(ekipage!O:O=A124)*(ISNUMBER(ekipage!Q:Q)=FALSE),0)),""),"")} | J124: {=IF(K124="Visa klasser",IFERROR(INDEX(ekipage!C:C, MATCH(1, (ekipage!O:O = A124) * (ISNUMBER(ekipage!Q:Q) = FALSE), 0)), "Ej individuell"),"Visar ej klasser")} -> Visar ej klasser | K124: Visa klasser ej
J125: {=IF(K125="Visa klasser",IFERROR(INDEX(ekipage!C:C, MATCH(1, (ekipage!O:O = A125) * (ISNUMBER(ekipage!Q:Q) = FALSE), 0)), "Ej individuell"),"Visar ej klasser")} -> Visar ej klasser | K125: Visa klasser ej
J126: {=IF(K126="Visa klasser",IFERROR(INDEX(ekipage!C:C, MATCH(1, (ekipage!O:O = A126) * (ISNUMBER(ekipage!Q:Q) = FALSE), 0)), "Ej individuell"),"Visar ej klasser")} -> Visar ej klasser | K126: Visa klasser ej
J127: {=IF(K127="Visa klasser",IFERROR(INDEX(ekipage!C:C, MATCH(1, (ekipage!O:O = A127) * (ISNUMBER(ekipage!Q:Q) = FALSE), 0)), "Ej individuell"),"Visar ej klasser")} -> Visar ej klasser | K127: Visa klasser ej
J128: {=IF(K128="Visa klasser",IFERROR(INDEX(ekipage!C:C, MATCH(1, (ekipage!O:O = A128) * (ISNUMBER(ekipage!Q:Q) = FALSE), 0)), "Ej individuell"),"Visar ej klasser")} -> Visar ej klasser | K128: Visa klasser ej
J129: {=IF(K129="Visa klasser",IFERROR(INDEX(ekipage!C:C, MATCH(1, (ekipage!O:O = A129) * (ISNUMBER(ekipage!Q:Q) = FALSE), 0)), "Ej individuell"),"Visar ej klasser")} -> Visar ej klasser | K129: Visa klasser ej
J130: {=IF(K130="Visa klasser",IFERROR(INDEX(ekipage!C:C, MATCH(1, (ekipage!O:O = A130) * (ISNUMBER(ekipage!Q:Q) = FALSE), 0)), "Ej individuell"),"Visar ej klasser")} -> Visar ej klasser | K130: Visa klasser ej
J131: {=IF(K131="Visa klasser",IFERROR(INDEX(ekipage!C:C, MATCH(1, (ekipage!O:O = A131) * (ISNUMBER(ekipage!Q:Q) = FALSE), 0)), "Ej individuell"),"Visar ej klasser")} -> Visar ej klasser | K131: Visa klasser ej
J132: {=IF(K132="Visa klasser",IFERROR(INDEX(ekipage!C:C, MATCH(1, (ekipage!O:O = A132) * (ISNUMBER(ekipage!Q:Q) = FALSE), 0)), "Ej individuell"),"Visar ej klasser")} -> Visar ej klasser
J133: {=IF(K133="Visa klasser",IFERROR(INDEX(ekipage!C:C, MATCH(1, (ekipage!O:O = A133) * (ISNUMBER(ekipage!Q:Q) = FALSE), 0)), "Ej individuell"),"Visar ej klasser")} -> Visar ej klasser
