Workbook

Sheet startlista
A1: 43 | B1: Skrittklass Lag grund och kür klass 15, 16
A2: 700 | B2: 999 | C2: P V - Skrittklass lag typ 1 | D2: 57688 | E2: Erika Hansen | F2: 339009 | G2: Odinn | J2: 223 | K2: Föreningen Uppsala Voltige | M2: Indus Blå | N2: 90 | O2: Elvira Androos | P2: 92 | Q2: Tilda Månsson | R2: 95 | S2: Felicia Söderman | T2: 99 | U2: Noomi Lind Polsk
A3: 700 | B3: 999 | C3: P V - Skrittklass lag typ 1 | D3: 57688 | E3: Erika Hansen | F3: 339009 | G3: Odinn | J3: 223 | K3: Föreningen Uppsala Voltige | M3: Indus Blå | N3: 90 | O3: Elvira Androos | P3: 92 | Q3: Tilda Månsson | R3: 95 | S3: Felicia Söderman | T3: 99 | U3: Noomi Lind Polsk
A4: 769951 | B4: 15 | C4: Skrittklass, lag typ 1 | D4: 36847 | E4: Linda Jenvall | F4: 280330 | G4: Calouha | J4: 223 | K4: Föreningen Uppsala Voltige | M4: Andromeda Svart | N4: 195029 | O4: Ariah Fischer | P4: 195002 | Q4: Elna Stidelius | R4: 194941 | S4: Nelia Palmius | T4: 202342 | U4: Alma Bjarnemo | V4: 195003 | W4: Sigrid Stidelius
A5: 769951 | B5: 15 | C5: Skrittklass, lag typ 1 | D5: 36847 | E5: Linda Jenvall | F5: 280330 | G5: Calouha | J5: 223 | K5: Föreningen Uppsala Voltige | M5: Andromeda Svart | N5: 195029 | O5: Ariah Fischer | P5: 195002 | Q5: Elna Stidelius | R5: 194941 | S5: Nelia Palmius | T5: 202342 | U5: Alma Bjarnemo | V5: 195003 | W5: Sigrid Stidelius
A6: 700 | B6: 999 | C6: P V - Skrittklass lag typ 1 | D6: 57688 | E6: Erika Hansen | F6: 339009 | G6: Odinn | J6: 223 | K6: Föreningen Uppsala Voltige | M6: Indus Gul | N6: 91 | O6: Selma Ouled El Housseine | P6: 93 | Q6: Signe Säfström | R6: 94 | S6: Mila Thulin | T6: 96 | U6: Hedvig Säfström
A7: 700 | B7: 999 | C7: P V - Skrittklass lag typ 1 | D7: 57688 | E7: Erika Hansen | F7: 339009 | G7: Odinn | J7: 223 | K7: Föreningen Uppsala Voltige | M7: Indus Gul | N7: 91 | O7: Selma Ouled El Housseine | P7: 93 | Q7: Signe Säfström | R7: 94 | S7: Mila Thulin | T7: 96 | U7: Hedvig Säfström
A8: 769951 | B8: 15 | C8: Skrittklass, lag typ 1 | D8: 36847 | E8: Linda Jenvall | F8: 280330 | G8: Calouha | J8: 223 | K8: Föreningen Uppsala Voltige | M8: Andromeda Blå | N8: 202327 | O8: Lovis Berg | P8: 202520 | Q8: Nikki Gladh | R8: 205893 | S8: Melina Vesterholm | T8: 194944 | U8: Linnéa Lif
A9: 769951 | B9: 15 | C9: Skrittklass, lag typ 1 | D9: 36847 | E9: Linda Jenvall | F9: 280330 | G9: Calouha | J9: 223 | K9: Föreningen Uppsala Voltige | M9: Andromeda Blå | N9: 202327 | O9: Lovis Berg | P9: 202520 | Q9: Nikki Gladh | R9: 205893 | S9: Melina Vesterholm | T9: 194944 | U9: Linnéa Lif
A10: 769952 | B10: 16 | C10: Skrittklass, lag typ 2 | D10: 180813 | E10: Jenny Rova | F10: 328098 | G10: Turbic Boy (SWB) | J10: 1330 | K10: Sala Voltige och Hästsportförening | M10: Eros | N10: 203576 | O10: Milou Hallgren | P10: 190728 | Q10: Meja Bergqvist | R10: 203579 | S10: Moa Jansson | T10: 206216 | U10: Julia Elvnäs | V10: 204013 | W10: Noelia Vega Santibanez
A11: 769952 | B11: 16 | C11: Skrittklass, lag typ 2 | D11: 180813 | E11: Jenny Rova | F11: 328098 | G11: Turbic Boy (SWB) | J11: 1330 | K11: Sala Voltige och Hästsportförening | M11: Eros | N11: 203576 | O11: Milou Hallgren | P11: 190728 | Q11: Meja Bergqvist | R11: 203579 | S11: Moa Jansson | T11: 206216 | U11: Julia Elvnäs | V11: 204013 | W11: Noelia Vega Santibanez
A12: 52 | B12: Mixklass klass 12
A13: 769949 | B13: 13 | C13: Mixklass 0* | D13: 49704 | E13: JoAnna Bäck | F13: 124 | G13: Orlando Van't Merodehof | J13: 1330 | K13: Sala Voltige och Hästsportförening | M13: Atlas | N13: 206123 | O13: Enzo Folgerö | P13: 171512 | Q13: Mira Bergqvist | R13: 181877 | S13: Mollie Strandberg | T13: 201304 | U13: Louise Hörnstedt | V13: 186888 | W13: Svea Torssander | X13: 200754 | Y13: Nova Lindgren
A14: 769949 | B14: 13 | C14: Mixklass 0* | D14: 49704 | E14: JoAnna Bäck | F14: 124 | G14: Orlando Van't Merodehof | J14: 1330 | K14: Sala Voltige och Hästsportförening | M14: Atlas | N14: 206123 | O14: Enzo Folgerö | P14: 171512 | Q14: Mira Bergqvist | R14: 181877 | S14: Mollie Strandberg | T14: 201304 | U14: Louise Hörnstedt | V14: 186888 | W14: Svea Torssander | X14: 200754 | Y14: Nova Lindgren
A15: 18 | B15: Svår klass lag seniorer klass 1 – Grund
A16: 769936 | B16: 1 | C16: Svår klass, Seniorlag | D16: 68838 | E16: Marie Johansson | F16: 308300 | G16: Gladiator VDH | J16: 1330 | K16: Sala Voltige och Hästsportförening | M16: Athena | N16: 164696 | O16: Amanda Lundén Pliscovaz | P16: 155903 | Q16: Julia Kristensson | R16: 206123 | S16: Enzo Folgerö | T16: 164698 | U16: Ellen Eriksson | V16: 203320 | W16: Malin Folgerö | X16: 195030 | Y16: Elly Malta
A17: 1 | B17: Svår klass individuella klass 3, 4, 5, 6, 7, 8 – Grund/tekn kür
A18: 769943 | B18: 7 | C18: Individuell junior 2* | D18: 40552 | E18: Annelie Lundgren | F18: 328352 | G18: Iniesta | J18: 869 | K18: Hamre Ridklubb | N18: 145535 | O18: Agnes Kumm
A19: 769939 | B19: 3 | C19: Individuell senior 3* | D19: 39162 | E19: Sofia Fågelsbo | F19: 342703 | G19: Serenade | J19: 1330 | K19: Sala Voltige och Hästsportförening | N19: 51513 | O19: Fanny Eklund
A20: 769943 | B20: 7 | C20: Individuell junior 2* | D20: 39162 | E20: Sofia Fågelsbo | F20: 342703 | G20: Serenade | J20: 223 | K20: Föreningen Uppsala Voltige | N20: 155140 | O20: Ebba Wallqvist
A21: 769939 | B21: 3 | C21: Individuell senior 3* | D21: 39162 | E21: Sofia Fågelsbo | F21: 342703 | G21: Serenade | J21: 1330 | K21: Sala Voltige och Hästsportförening | N21: 99453 | O21: Emilia Bäck
A22: 769943 | B22: 7 | C22: Individuell junior 2* | D22: 65038 | E22: Christina Müller | F22: 312598 | G22: Diamond | J22: 223 | K22: Föreningen Uppsala Voltige | N22: 101580 | O22: Linnea Jennische
A23: 769940 | B23: 4 | C23: Individuell senior 2* | D23: 44766 | E23: Andrea Raud | F23: 293254 | G23: Cortesch (SWB) | J23: 223 | K23: Föreningen Uppsala Voltige | N23: 124472 | O23: Ebba Holmberg
A24: 769943 | B24: 7 | C24: Individuell junior 2* | D24: 44766 | E24: Andrea Raud | F24: 293254 | G24: Cortesch (SWB) | J24: 223 | K24: Föreningen Uppsala Voltige | N24: 163943 | O24: Wilma Ericson Flack
A25: 769944 | B25: 8 | C25: Individuell junior 1* | D25: 39667 | E25: Linda Viklund | F25: 342894 | G25: Charlz (SWB) | J25: 986 | K25: Timrå Hästsportförening | N25: 155124 | O25: Agnes Viklund
A26: 769944 | B26: 8 | C26: Individuell junior 1* | D26: 39667 | E26: Linda Viklund | F26: 342894 | G26: Charlz (SWB) | J26: 986 | K26: Timrå Hästsportförening | N26: 200328 | O26: Olivia Nyberg
A27: 769939 | B27: 3 | C27: Individuell senior 3* | D27: 39162 | E27: Sofia Fågelsbo | F27: 342703 | G27: Serenade | J27: 1330 | K27: Sala Voltige och Hästsportförening | N27: 51513 | O27: Fanny Eklund
A28: 769939 | B28: 3 | C28: Individuell senior 3* | D28: 39162 | E28: Sofia Fågelsbo | F28: 342703 | G28: Serenade | J28: 1330 | K28: Sala Voltige och Hästsportförening | N28: 99453 | O28: Emilia Bäck
A29: 769940 | B29: 4 | C29: Individuell senior 2* | D29: 40552 | E29: Annelie Lundgren | F29: 354215 | G29: Crisanto S | J29: 869 | K29: Hamre Ridklubb | N29: 106236 | O29: My Lindström
... A38: 769943 | B38: 7 | C38: Individuell junior 2* | D38: 40552 | E38: Annelie Lundgren | F38: 330385 | G38: Klondike | J38: 869 | K38: Hamre Ridklubb | N38: 98 | O38: Agnes_Kumm
A39: 46 | B39: Skrittklass, Lätt klass, individuell 17, 18
A40: 769953 | B40: 17 | C40: Lättklass, Individuell | D40: 65539 | E40: Connie Rebane | F40: 262992 | G40: Hembys Bellman | J40: 869 | K40: Hamre Ridklubb | N40: 195035 | O40: Haylie Rebane
A41: 769953 | B41: 17 | C41: Lättklass, Individuell | D41: 65539 | E41: Connie Rebane | F41: 262992 | G41: Hembys Bellman | J41: 869 | K41: Hamre Ridklubb | N41: 195035 | O41: Haylie Rebane
A42: 769953 | B42: 17 | C42: Lättklass, Individuell | D42: 34557 | E42: Maria Kumm | F42: 262992 | G42: Hembys Bellman | J42: 869 | K42: Hamre Ridklubb | N42: 195019 | O42: Ebba Fasthamre
A43: 769953 | B43: 17 | C43: Lättklass, Individuell | D43: 34557 | E43: Maria Kumm | F43: 262992 | G43: Hembys Bellman | J43: 869 | K43: Hamre Ridklubb | N43: 195019 | O43: Ebba Fasthamre
A44: 769953 | B44: 17 | C44: Lättklass, Individuell | D44: 96828 | E44: Anna-Tuva Andersson | F44: 334748 | G44: Silver | J44: 1330 | K44: Sala Voltige och Hästsportförening | N44: 206243 | O44: Elsa Söderberg
A45: 769953 | B45: 17 | C45: Lättklass, Individuell | D45: 96828 | E45: Anna-Tuva Andersson | F45: 334748 | G45: Silver | J45: 1330 | K45: Sala Voltige och Hästsportförening | N45: 206243 | O45: Elsa Söderberg
A46: 769953 | B46: 17 | C46: Lättklass, Individuell | D46: 180813 | E46: Jenny Rova | F46: 328098 | G46: Turbic Boy (SWB) | J46: 1330 | K46: Sala Voltige och Hästsportförening | N46: 29744 | O46: Denice Sundberg
A47: 769953 | B47: 17 | C47: Lättklass, Individuell | D47: 180813 | E47: Jenny Rova | F47: 328098 | G47: Turbic Boy (SWB) | J47: 986 | K47: Timrå Hästsportförening | N47: 169428 | O47: Cecilia Viklund
A48: 769953 | B48: 17 | C48: Lättklass, Individuell | D48: 180813 | E48: Jenny Rova | F48: 328098 | G48: Turbic Boy (SWB) | J48: 986 | K48: Timrå Hästsportförening | N48: 186749 | O48: Tyra Karlsson
...

Sheet startlisteklasser
A1: 45935.417 | B1: 43 | C1: Skrittklass Lag grund och kür klass 15, 16 | D1: 700 | E1: 999 | F1: P V - Skrittklass lag typ 1 | G1: 1
B2: 43 | C2: Skrittklass Lag grund och kür klass 15, 16 | D2: 700 | E2: 999 | F2: P V - Skrittklass lag typ 1 | G2: 2
B3: 43 | C3: Skrittklass Lag grund och kür klass 15, 16 | D3: 769951 | E3: 15 | F3: Skrittklass, lag typ 1 | G3: 1
B4: 43 | C4: Skrittklass Lag grund och kür klass 15, 16 | D4: 769951 | E4: 15 | F4: Skrittklass, lag typ 1 | G4: 2
B5: 43 | C5: Skrittklass Lag grund och kür klass 15, 16 | D5: 769952 | E5: 16 | F5: Skrittklass, lag typ 2 | G5: 1
B6: 43 | C6: Skrittklass Lag grund och kür klass 15, 16 | D6: 769952 | E6: 16 | F6: Skrittklass, lag typ 2 | G6: 2
B7: 52 | C7: Mixklass klass 12 | D7: 769949 | E7: 13 | F7: Mixklass 0* | G7: 1
B8: 52 | C8: Mixklass klass 12 | D8: 769949 | E8: 13 | F8: Mixklass 0* | G8: 2
B9: 18 | C9: Svår klass lag seniorer klass 1 – Grund | D9: 769936 | E9: 1 | F9: Svår klass, Seniorlag | G9: 1
B10: 1 | C10: Svår klass individuella klass 3, 4, 5, 6, 7, 8 – Grund/tekn kür | D10: 769939 | E10: 3 | F10: Individuell senior 3* | G10: 1
B11: 1 | C11: Svår klass individuella klass 3, 4, 5, 6, 7, 8 – Grund/tekn kür | D11: 769939 | E11: 3 | F11: Individuell senior 3* | G11: 2
B12: 1 | C12: Svår klass individuella klass 3, 4, 5, 6, 7, 8 – Grund/tekn kür | D12: 769940 | E12: 4 | F12: Individuell senior 2* | G12: 1
B13: 1 | C13: Svår klass individuella klass 3, 4, 5, 6, 7, 8 – Grund/tekn kür | D13: 769941 | E13: 5 | F13: Individuell senior 1* | G13: 1
... B30: 2 | C30: Svår klass individuella klass 3, 4, 5, 6, 7, 8 – Kür | D30: 769945 | E30: 9 | F30: Individuell minior 1* | G30: 2

Sheet ekipage
A1: 700 | B1: 999 | C1: P V - Skrittklass lag typ 1 | D1: 57688 | E1: Erika Hansen | F1: 339009 | G1: Odinn | J1: 223 | K1: Föreningen Uppsala Voltige | M1: Indus Blå | N1: 90 | O1: Elvira Androos | P1: 92 | Q1: Tilda Månsson | R1: 95 | S1: Felicia Söderman | T1: 99 | U1: Noomi Lind Polsk
A2: 769951 | B2: 15 | C2: Skrittklass, lag typ 1 | D2: 36847 | E2: Linda Jenvall | F2: 280330 | G2: Calouha | J2: 223 | K2: Föreningen Uppsala Voltige | L2: Uppsala Team Andromeda, , Startordning: Ariah, Elna, Nelia, Alma, Sigrid. | M2: Andromeda Svart | N2: 195029 | O2: Ariah Fischer | P2: 195002 | Q2: Elna Stidelius | R2: 194941 | S2: Nelia Palmius | T2: 202342 | U2: Alma Bjarnemo | V2: 195003 | W2: Sigrid Stidelius
A3: 700 | B3: 999 | C3: P V - Skrittklass lag typ 1 | D3: 57688 | E3: Erika Hansen | F3: 339009 | G3: Odinn | J3: 223 | K3: Föreningen Uppsala Voltige | M3: Indus Gul | N3: 91 | O3: Selma Ouled El Housseine | P3: 93 | Q3: Signe Säfström | R3: 94 | S3: Mila Thulin | T3: 96 | U3: Hedvig Säfström
A4: 769936 | B4: 1 | C4: Svår klass, Seniorlag | D4: 68838 | E4: Marie Johansson | F4: 308300 | G4: Gladiator VDH | J4: 1330 | K4: Sala Voltige och Hästsportförening | M4: Athena | N4: 164696 | O4: Amanda Lundén Pliscovaz | P4: 155903 | Q4: Julia Kristensson | R4: 206123 | S4: Enzo Folgerö | T4: 164698 | U4: Ellen Eriksson | V4: 203320 | W4: Malin Folgerö | X4: 195030 | Y4: Elly Malta
A5: 769943 | B5: 7 | C5: Individuell junior 2* | D5: 40552 | E5: Annelie Lundgren | F5: 328352 | G5: Iniesta | J5: 869 | K5: Hamre Ridklubb | L5: Så långt som möjligt mellan Iniesta och Klondike | N5: 145535 | O5: Agnes Kumm
A6: 769939 | B6: 3 | C6: Individuell senior 3* | D6: 39162 | E6: Sofia Fågelsbo | F6: 342703 | G6: Serenade | J6: 1330 | K6: Sala Voltige och Hästsportförening | L6: Grund och teknisk i olika inspring. Ordning Fanny,Ebba,Emilia | N6: 51513 | O6: Fanny Eklund
A7: 769943 | B7: 7 | C7: Individuell junior 2* | D7: 65038 | E7: Christina Müller | F7: 312598 | G7: Diamond | J7: 223 | K7: Föreningen Uppsala Voltige | N7: 101580 | O7: Linnea Jennische
A8: 769940 | B8: 4 | C8: Individuell senior 2* | D8: 44766 | E8: Andrea Raud | F8: 293254 | G8: Cortesch (SWB) | J8: 223 | K8: Föreningen Uppsala Voltige | N8: 124472 | O8: Ebba Holmberg
A9: 769944 | B9: 8 | C9: Individuell junior 1* | D9: 39667 | E9: Linda Viklund | F9: 342894 | G9: Charlz (SWB) | J9: 986 | K9: Timrå Hästsportförening | N9: 155124 | O9: Agnes Viklund
A10: 769940 | B10: 4 | C10: Individuell senior 2* | D10: 40552 | E10: Annelie Lundgren | F10: 354215 | G10: Crisanto S | J10: 869 | K10: Hamre Ridklubb | N10: 106236 | O10: My Lindström
A11: 769940 | B11: 4 | C11: Individuell senior 2* | D11: 44766 | E11: Andrea Raud | F11: 123 | G11: Cortesch_(SWB) | J11: 223 | K11: Föreningen Uppsala Voltige | N11: 160950 | O11: Thea Lundell
A12: 769941 | B12: 5 | C12: Individuell senior 1* | D12: 39667 | E12: Linda Viklund | F12: 125 | G12: Charlz_(SWB) | J12: 986 | K12: Timrå Hästsportförening | N12: 134303 | O12: Henny Lind
A13: 769940 | B13: 4 | C13: Individuell senior 2* | D13: 36847 | E13: Linda Jenvall | F13: 280330 | G13: Calouha | J13: 223 | K13: Föreningen Uppsala Voltige | N13: 101407 | O13: Tindra Öberg
A14: 769943 | B14: 7 | C14: Individuell junior 2* | D14: 24976 | E14: Cecilia Rasmussen | F14: 316201 | G14: Farrakech (SWB) | J14: 1330 | K14: Sala Voltige och Hästsportförening | N14: 155915 | O14: Isabelle Rasmussen
A15: 769943 | B15: 7 | C15: Individuell junior 2* | D15: 39162 | E15: Sofia Fågelsbo | F15: 342703 | G15: Serenade | J15: 223 | K15: Föreningen Uppsala Voltige | N15: 155140 | O15: Ebba Wallqvist
A16: 769939 | B16: 3 | C16: Individuell senior 3* | D16: 39162 | E16: Sofia Fågelsbo | F16: 342703 | G16: Serenade | J16: 1330 | K16: Sala Voltige och Hästsportförening | L16: Startordning:, 1. Fanny Eklund , 2. Ebba Wallqvist , 3. Emilia Bäck , , Grund och tekniskt i olika inspring | N16: 99453 | O16: Emilia Bäck
A17: 769940 | B17: 4 | C17: Individuell senior 2* | D17: 36847 | E17: Linda Jenvall | F17: 280330 | G17: Calouha | J17: 223 | K17: Föreningen Uppsala Voltige | N17: 119893 | O17: Novalie Wall
A18: 769943 | B18: 7 | C18: Individuell junior 2* | D18: 24976 | E18: Cecilia Rasmussen | F18: 316201 | G18: Farrakech (SWB) | J18: 223 | K18: Föreningen Uppsala Voltige | L18: Elda tävlar för Uppsala Voltige | N18: 155892 | O18: Elda Lindberg
A19: 769943 | B19: 7 | C19: Individuell junior 2* | D19: 44766 | E19: Andrea Raud | F19: 293254 | G19: Cortesch (SWB) | J19: 223 | K19: Föreningen Uppsala Voltige | N19: 163943 | O19: Wilma Ericson Flack
A20: 769943 | B20: 7 | C20: Individuell junior 2* | D20: 40552 | E20: Annelie Lundgren | F20: 354215 | G20: Crisanto S | J20: 869 | K20: Hamre Ridklubb | N20: 134608 | O20: Linnea Pedersen
A21: 769944 | B21: 8 | C21: Individuell junior 1* | D21: 39667 | E21: Linda Viklund | F21: 342894 | G21: Charlz (SWB) | J21: 986 | K21: Timrå Hästsportförening | N21: 200328 | O21: Olivia Nyberg
A22: 769945 | B22: 9 | C22: Individuell minior 1* | D22: 44766 | E22: Andrea Raud | F22: 123 | G22: Cortesch_(SWB) | J22: 223 | K22: Föreningen Uppsala Voltige | L22: Missade att fylla i ”sena ändringar” och önskar det som tillägg. | N22: 190842 | O22: Vera Bjarnemo
A23: 769943 | B23: 7 | C23: Individuell junior 2* | D23: 40552 | E23: Annelie Lundgren | F23: 330385 | G23: Klondike | J23: 869 | K23: Hamre Ridklubb | L23: Så långt som möjligt mellan Iniesta och Klondike. , Klondike är helt ny och detta är hans första tävling. | N23: 98 | O23: Agnes_Kumm
A24: 769951 | B24: 15 | C24: Skrittklass, lag typ 1 | D24: 36847 | E24: Linda Jenvall | F24: 280330 | G24: Calouha | J24: 223 | K24: Föreningen Uppsala Voltige | L24: Uppsala Team Andromeda Blå, , Det andra laget kan heta Andromeda Svart | M24: Andromeda Blå | N24: 202327 | O24: Lovis Berg | P24: 202520 | Q24: Nikki Gladh | R24: 205893 | S24: Melina Vesterholm | T24: 194944 | U24: Linnéa Lif
A25: 769952 | B25: 16 | C25: Skrittklass, lag typ 2 | D25: 180813 | E25: Jenny Rova | F25: 328098 | G25: Turbic Boy (SWB) | J25: 1330 | K25: Sala Voltige och Hästsportförening | L25: Team Eros , Startordning:, 1. Milou Hallgren, 2. Meja Bergqvist, 3. Moa Jansson, 4. Julia Elvnäs , 5. Noelia Vega Santibanez | M25: Eros | N25: 203576 | O25: Milou Hallgren | P25: 190728 | Q25: Meja Bergqvist | R25: 203579 | S25: Moa Jansson | T25: 206216 | U25: Julia Elvnäs | V25: 204013 | W25: Noelia Vega Santibanez
A26: 769949 | B26: 13 | C26: Mixklass 0* | D26: 49704 | E26: JoAnna Bäck | F26: 124 | G26: Orlando Van't Merodehof | J26: 1330 | K26: Sala Voltige och Hästsportförening | L26: Team Atlas, Startordning, 1 Mollie strandberg , 2 Nova Lindgren , 3 Enzo folgerö , 4 Mira Bergqvist, 5 Louise Hörnstedt, 6 Svea Torssander | M26: Atlas | N26: 206123 | O26: Enzo Folgerö | P26: 171512 | Q26: Mira Bergqvist | R26: 181877 | S26: Mollie Strandberg | T26: 201304 | U26: Louise Hörnstedt | V26: 186888 | W26: Svea Torssander | X26: 200754 | Y26: Nova Lindgren
A27: 769953 | B27: 17 | C27: Lättklass, Individuell | D27: 65539 | E27: Connie Rebane | F27: 262992 | G27: Hembys Bellman | J27: 869 | K27: Hamre Ridklubb | L27: Mia kumm linför, connie värmer upp, | N27: 195035 | O27: Haylie Rebane
A28: 769953 | B28: 17 | C28: Lättklass, Individuell | D28: 34557 | E28: Maria Kumm | F28: 262992 | G28: Hembys Bellman | J28: 869 | K28: Hamre Ridklubb | N28: 195019 | O28: Ebba Fasthamre
A29: 769953 | B29: 17 | C29: Lättklass, Individuell | D29: 96828 | E29: Anna-Tuva Andersson | F29: 334748 | G29: Silver | J29: 1330 | K29: Sala Voltige och Hästsportförening | N29: 206243 | O29: Elsa Söderberg
A30: 769953 | B30: 17 | C30: Lättklass, Individuell | D30: 180813 | E30: Jenny Rova | F30: 328098 | G30: Turbic Boy (SWB) | J30: 1330 | K30: Sala Voltige och Hästsportförening | N30: 29744 | O30: Denice Sundberg
A31: 769953 | B31: 17 | C31: Lättklass, Individuell | D31: 180813 | E31: Jenny Rova | F31: 328098 | G31: Turbic Boy (SWB) | J31: 986 | K31: Timrå Hästsportförening | L31: Höger varv | N31: 169428 | O31: Cecilia Viklund
A32: 769953 | B32: 17 | C32: Lättklass, Individuell | D32: 180813 | E32: Jenny Rova | F32: 328098 | G32: Turbic Boy (SWB) | J32: 986 | K32: Timrå Hästsportförening | L32: Höger varv | N32: 186749 | O32: Tyra Karlsson
A33: 769953 | B33: 17 | C33: Lättklass, Individuell | D33: 24976 | E33: Cecilia Rasmussen | F33: 316201 | G33: Farrakech (SWB) | J33: 1330 | K33: Sala Voltige och Hästsportförening | N33: 163633 | O33: Julia Ekblom
A34: 769953 | B34: 17 | C34: Lättklass, Individuell | D34: 49704 | E34: JoAnna Bäck | F34: 124 | G34: Orlando Van't Merodehof | J34: 1330 | K34: Sala Voltige och Hästsportförening | N34: 181877 | O34: Mollie Strandberg
A35: 769954 | B35: 18 | C35: Skrittklass, individuell | D35: 68838 | E35: Marie Johansson | F35: 308300 | G35: Gladiator VDH | J35: 223 | K35: Föreningen Uppsala Voltige | L35: Tävlar för Uppsala Voltige | N35: 202327 | O35: Lovis Berg
A36: 769954 | B36: 18 | C36: Skrittklass, individuell | D36: 57688 | E36: Erika Hansen | F36: 339009 | G36: Odinn | J36: 223 | K36: Föreningen Uppsala Voltige | L36: Tävlar för Uppsala Voltige | N36: 194944 | O36: Linnéa Lif
A37: 769954 | B37: 18 | C37: Skrittklass, individuell | D37: 39162 | E37: Sofia Fågelsbo | F37: 342703 | G37: Serenade | J37: 223 | K37: Föreningen Uppsala Voltige | L37: Tävlar för Uppsala Voltige | N37: 202520 | O37: Nikki Gladh
A38: 769954 | B38: 18 | C38: Skrittklass, individuell | D38: 180813 | E38: Jenny Rova | F38: 328098 | G38: Turbic Boy (SWB) | J38: 986 | K38: Timrå Hästsportförening | N38: 186751 | O38: Sofia Ekström
A39: 769954 | B39: 18 | C39: Skrittklass, individuell | D39: 39162 | E39: Sofia Fågelsbo | F39: 342703 | G39: Serenade | J39: 223 | K39: Föreningen Uppsala Voltige | L39: Tävlar för Uppsala Voltige | N39: 195002 | O39: Elna Stidelius
A40: 769954 | B40: 18 | C40: Skrittklass, individuell | D40: 57688 | E40: Erika Hansen | F40: 339009 | G40: Odinn | J40: 223 | K40: Föreningen Uppsala Voltige | L40: Tävlar för Uppsala Voltige | N40: 202342 | O40: Alma Bjarnemo
...

Sheet klasser
A1: 769936 | B1: 1 | C1: Svår klass, Seniorlag | D1: 1
A2: 769937 | B2: 2 | C2: Svår klass, Juniorlag | D2: 13
A3: 769939 | B3: 3 | C3: Individuell senior 3* | D3: 25
A4: 769940 | B4: 4 | C4: Individuell senior 2* | D4: 1076
A5: 769941 | B5: 5 | C5: Individuell senior 1* | D5: 1077
A6: 769942 | B6: 6 | C6: Individuell young vaulter | D6: 1060
A7: 769943 | B7: 7 | C7: Individuell junior 2* | D7: 33 | E7: 33 3 domare 34 för 4 domare
A8: 769944 | B8: 8 | C8: Individuell junior 1* | D8: 1078
A9: 769945 | B9: 9 | C9: Individuell minior 1* | D9: 37
A10: 769946 | B10: 10 | C10: Pas de deux
A11: 769947 | B11: 11 | C11: Mellanklass, lag
A12: 769948 | B12: 12 | C12: Mixklass 1* | D12: 1054
A13: 769949 | B13: 13 | C13: Mixklass 0* | D13: 47 | E13: 50 för 3 domare
A14: 769950 | B14: 14 | C14: Lättklass, lag | D14: 1095
A15: 769951 | B15: 15 | C15: Skrittklass, lag typ 1 | D15: 44 | E15: 44 2 domare | F15: 51 3 domare
A16: 769952 | B16: 16 | C16: Skrittklass, lag typ 2 | D16: 1058 | E16: 1058 2 domare | F16: 1059 3 domare
A17: 769953 | B17: 17 | C17: Lättklass, Individuell | D17: 48 | E17: 43 2 domare
A18: 769954 | B18: 18 | C18: Skrittklass, individuell | D18: 49 | E18: 45 2 domare
A19: 769955 | B19: 19 | C19: Skrittklass, pas de deux | D19: 1056 | E19: 1055 2 domare
A20: 700 | B20: 999 | C20: P V - Skrittklass lag typ 1 | D20: 44 | E20: 52 = mer än 6 deltagare

Sheet linförare
A1: 68838 | B1: Marie Johansson
A2: 39162 | B2: Sofia Fågelsbo
A3: 36847 | B3: Linda Jenvall
A4: 44766 | B4: Andrea Raud
A5: 40552 | B5: Annelie Lundgren
A6: 39667 | B6: Linda Viklund
A7: 24976 | B7: Cecilia Rasmussen
A8: 65038 | B8: Christina Müller
A9: 95073 | B9: Angelica Thunman
A10: 49704 | B10: JoAnna Bäck
A11: 180813 | B11: Jenny Rova
A12: 65539 | B12: Connie Rebane
... A15: 57688 | B15: Erika Hansen

Sheet reservhästar
A1: 0 | B1: -
A2: 262992 | B2: Hembys Bellman

Sheet hästar
A1: 308300 | B1: Gladiator VDH
A2: 342703 | B2: Serenade
A3: 280330 | B3: Calouha
A4: 293254 | B4: Cortesch (SWB)
A5: 354215 | B5: Crisanto S
A6: 342894 | B6: Charlz (SWB)
A7: 316201 | B7: Farrakech (SWB)
A8: 312598 | B8: Diamond
A9: 321025 | B9: Castell (SWB)
A10: 328352 | B10: Iniesta
A11: 279357 | B11: Halving
A12: 330385 | B12: Klondike
... A21: 125 | B21: Charlz_(SWB)

Sheet klubbar
A1: 1330 | B1: Sala Voltige och Hästsportförening | C1: SE
A2: 233 | B2: Lagga Fältrittklubb | C2: SE
A3: 223 | B3: Föreningen Uppsala Voltige | C3: SE
A4: 869 | B4: Hamre Ridklubb | C4: SE
A5: 986 | B5: Timrå Hästsportförening | C5: SE
A6: 1198 | B6: Fortuna Voltigeförening | C6: SE
A7: 867 | B7: Föreningen Skästa Ridcenter | C7: SE

Sheet voltigörer
A1: 51513 | B1: Fanny Eklund | C1: Svart 7 | I1: {=IF(K1="Visa klasser",IFERROR(INDEX(ekipage!B:B,MATCH(1,(ekipage!N:N=A1)*(ISNUMBER(ekipage!P:P)=FALSE),0)),""),"")} -> 3 | J1: {=IF(K1="Visa klasser",IFERROR(INDEX(ekipage!C:C, MATCH(1, (ekipage!N:N = A1) * (ISNUMBER(ekipage!P:P) = FALSE), 0)), "Ej individuell"),"Visar ej klasser")} -> Individuell senior 3* | K1: Visa klasser
A2: 99453 | B2: Emilia Bäck | C2: Svart 8 | I2: {=IF(K2="Visa klasser",IFERROR(INDEX(ekipage!B:B,MATCH(1,(ekipage!N:N=A2)*(ISNUMBER(ekipage!P:P)=FALSE),0)),""),"")} -> 3 | J2: {=IF(K2="Visa klasser",IFERROR(INDEX(ekipage!C:C, MATCH(1, (ekipage!N:N = A2) * (ISNUMBER(ekipage!P:P) = FALSE), 0)), "Ej individuell"),"Visar ej klasser")} -> Individuell senior 3* | K2: Visa klasser
A3: 101407 | B3: Tindra Öberg | C3: Vit 19 | I3: {=IF(K3="Visa klasser",IFERROR(INDEX(ekipage!B:B,MATCH(1,(ekipage!N:N=A3)*(ISNUMBER(ekipage!P:P)=FALSE),0)),""),"")} -> 4 | J3: {=IF(K3="Visa klasser",IFERROR(INDEX(ekipage!C:C, MATCH(1, (ekipage!N:N = A3) * (ISNUMBER(ekipage!P:P) = FALSE), 0)), "Ej individuell"),"Visar ej klasser")} -> Individuell senior 2* | K3: Visa klasser
A4: 106236 | B4: My Lindström | C4: Vit 1 | I4: {=IF(K4="Visa klasser",IFERROR(INDEX(ekipage!B:B,MATCH(1,(ekipage!N:N=A4)*(ISNUMBER(ekipage!P:P)=FALSE),0)),""),"")} -> 4 | J4: {=IF(K4="Visa klasser",IFERROR(INDEX(ekipage!C:C, MATCH(1, (ekipage!N:N = A4) * (ISNUMBER(ekipage!P:P) = FALSE), 0)), "Ej individuell"),"Visar ej klasser")} -> Individuell senior 2* | K4: Visa klasser
A5: 119893 | B5: Novalie Wall | C5: Vit 7 | I5: {=IF(K5="Visa klasser",IFERROR(INDEX(ekipage!B:B,MATCH(1,(ekipage!N:N=A5)*(ISNUMBER(ekipage!P:P)=FALSE),0)),""),"")} -> 4 | J5: {=IF(K5="Visa klasser",IFERROR(INDEX(ekipage!C:C, MATCH(1, (ekipage!N:N = A5) * (ISNUMBER(ekipage!P:P) = FALSE), 0)), "Ej individuell"),"Visar ej klasser")} -> Individuell senior 2* | K5: Visa klasser
A6: 124472 | B6: Ebba Holmberg | C6: Vit 8 | I6: {=IF(K6="Visa klasser",IFERROR(INDEX(ekipage!B:B,MATCH(1,(ekipage!N:N=A6)*(ISNUMBER(ekipage!P:P)=FALSE),0)),""),"")} -> 4 | J6: {=IF(K6="Visa klasser",IFERROR(INDEX(ekipage!C:C, MATCH(1, (ekipage!N:N = A6) * (ISNUMBER(ekipage!P:P) = FALSE), 0)), "Ej individuell"),"Visar ej klasser")} -> Individuell senior 2* | K6: Visa klasser
A7: 160950 | B7: Thea Lundell | C7: Vit 10 | I7: {=IF(K7="Visa klasser",IFERROR(INDEX(ekipage!B:B,MATCH(1,(ekipage!N:N=A7)*(ISNUMBER(ekipage!P:P)=FALSE),0)),""),"")} -> 4 | J7: {=IF(K7="Visa klasser",IFERROR(INDEX(ekipage!C:C, MATCH(1, (ekipage!N:N = A7) * (ISNUMBER(ekipage!P:P) = FALSE), 0)), "Ej individuell"),"Visar ej klasser")} -> Individuell senior 2* | K7: Visa klasser
A8: 134303 | B8: Henny Lind | C8: Blå 1 | I8: {=IF(K8="Visa klasser",IFERROR(INDEX(ekipage!B:B,MATCH(1,(ekipage!N:N=A8)*(ISNUMBER(ekipage!P:P)=FALSE),0)),""),"")} -> 5 | J8: {=IF(K8="Visa klasser",IFERROR(INDEX(ekipage!C:C, MATCH(1, (ekipage!N:N = A8) * (ISNUMBER(ekipage!P:P) = FALSE), 0)), "Ej individuell"),"Visar ej klasser")} -> Individuell senior 1* | K8: Visa klasser
A9: 97 | B9: Sofia Ekström | I9: {=IF(K9="Visa klasser",IFERROR(INDEX(ekipage!B:B,MATCH(1,(ekipage!N:N=A9)*(ISNUMBER(ekipage!P:P)=FALSE),0)),""),"")} | J9: {=IF(K9="Visa klasser",IFERROR(INDEX(ekipage!C:C, MATCH(1, (ekipage!N:N = A9) * (ISNUMBER(ekipage!P:P) = FALSE), 0)), "Ej individuell"),"Visar ej klasser")} -> Ej individuell | K9: Visa klasser
A10: 98 | B10: Agnes_Kumm | C10: Vit 12 | I10: {=IF(K10="Visa klasser",IFERROR(INDEX(ekipage!B:B,MATCH(1,(ekipage!N:N=A10)*(ISNUMBER(ekipage!P:P)=FALSE),0)),""),"")} -> 7 | J10: {=IF(K10="Visa klasser",IFERROR(INDEX(ekipage!C:C, MATCH(1, (ekipage!N:N = A10) * (ISNUMBER(ekipage!P:P) = FALSE), 0)), "Ej individuell"),"Visar ej klasser")} -> Individuell junior 2* | K10: Visa klasser
A11: 101580 | B11: Linnea Jennische | C11: Vit 13 | I11: {=IF(K11="Visa klasser",IFERROR(INDEX(ekipage!B:B,MATCH(1,(ekipage!N:N=A11)*(ISNUMBER(ekipage!P:P)=FALSE),0)),""),"")} -> 7 | J11: {=IF(K11="Visa klasser",IFERROR(INDEX(ekipage!C:C, MATCH(1, (ekipage!N:N = A11) * (ISNUMBER(ekipage!P:P) = FALSE), 0)), "Ej individuell"),"Visar ej klasser")} -> Individuell junior 2* | K11: Visa klasser
A12: 129688 | B12: Ella Eriksson | I12: {=IF(K12="Visa klasser",IFERROR(INDEX(ekipage!B:B,MATCH(1,(ekipage!N:N=A12)*(ISNUMBER(ekipage!P:P)=FALSE),0)),""),"")} | J12: {=IF(K12="Visa klasser",IFERROR(INDEX(ekipage!C:C, MATCH(1, (ekipage!N:N = A12) * (ISNUMBER(ekipage!P:P) = FALSE), 0)), "Ej individuell"),"Visar ej klasser")} -> Ej individuell | K12: Visa klasser
A13: 134608 | B13: Linnea Pedersen | C13: Vit 15 | I13: {=IF(K13="Visa klasser",IFERROR(INDEX(ekipage!B:B,MATCH(1,(ekipage!N:N=A13)*(ISNUMBER(ekipage!P:P)=FALSE),0)),""),"")} -> 7 | J13: {=IF(K13="Visa klasser",IFERROR(INDEX(ekipage!C:C, MATCH(1, (ekipage!N:N = A13) * (ISNUMBER(ekipage!P:P) = FALSE), 0)), "Ej individuell"),"Visar ej klasser")} -> Individuell junior 2* | K13: Visa klasser
A14: 145535 | B14: Agnes Kumm | C14: Vit 12 | I14: {=IF(K14="Visa klasser",IFERROR(INDEX(ekipage!B:B,MATCH(1,(ekipage!N:N=A14)*(ISNUMBER(ekipage!P:P)=FALSE),0)),""),"")} -> 7 | J14: {=IF(K14="Visa klasser",IFERROR(INDEX(ekipage!C:C, MATCH(1, (ekipage!N:N = A14) * (ISNUMBER(ekipage!P:P) = FALSE), 0)), "Ej individuell"),"Visar ej klasser")} -> Individuell junior 2* | K14: Visa klasser
A15: 155140 | B15: Ebba Wallqvist | C15: Vit 16 | I15: {=IF(K15="Visa klasser",IFERROR(INDEX(ekipage!B:B,MATCH(1,(ekipage!N:N=A15)*(ISNUMBER(ekipage!P:P)=FALSE),0)),""),"")} -> 7 | J15: {=IF(K15="Visa klasser",IFERROR(INDEX(ekipage!C:C, MATCH(1, (ekipage!N:N = A15) * (ISNUMBER(ekipage!P:P) = FALSE), 0)), "Ej individuell"),"Visar ej klasser")} -> Individuell junior 2* | K15: Visa klasser
A16: 155892 | B16: Elda Lindberg | C16: Vit 17 | I16: {=IF(K16="Visa klasser",IFERROR(INDEX(ekipage!B:B,MATCH(1,(ekipage!N:N=A16)*(ISNUMBER(ekipage!P:P)=FALSE),0)),""),"")} -> 7 | J16: {=IF(K16="Visa klasser",IFERROR(INDEX(ekipage!C:C, MATCH(1, (ekipage!N:N = A16) * (ISNUMBER(ekipage!P:P) = FALSE), 0)), "Ej individuell"),"Visar ej klasser")} -> Individuell junior 2* | K16: Visa klasser
A17: 155915 | B17: Isabelle Rasmussen | C17: Vit 18 | I17: {=IF(K17="Visa klasser",IFERROR(INDEX(ekipage!B:B,MATCH(1,(ekipage!N:N=A17)*(ISNUMBER(ekipage!P:P)=FALSE),0)),""),"")} -> 7 | J17: {=IF(K17="Visa klasser",IFERROR(INDEX(ekipage!C:C, MATCH(1, (ekipage!N:N = A17) * (ISNUMBER(ekipage!P:P) = FALSE), 0)), "Ej individuell"),"Visar ej klasser")} -> Individuell junior 2* | K17: Visa klasser
A18: 163943 | B18: Wilma Ericson Flack | C18: Vit 20 | I18: {=IF(K18="Visa klasser",IFERROR(INDEX(ekipage!B:B,MATCH(1,(ekipage!N:N=A18)*(ISNUMBER(ekipage!P:P)=FALSE),0)),""),"")} -> 7 | J18: {=IF(K18="Visa klasser",IFERROR(INDEX(ekipage!C:C, MATCH(1, (ekipage!N:N = A18) * (ISNUMBER(ekipage!P:P) = FALSE), 0)), "Ej individuell"),"Visar ej klasser")} -> Individuell junior 2* | K18: Visa klasser
A19: 155124 | B19: Agnes Viklund | C19: Blå 2 | I19: {=IF(K19="Visa klasser",IFERROR(INDEX(ekipage!B:B,MATCH(1,(ekipage!N:N=A19)*(ISNUMBER(ekipage!P:P)=FALSE),0)),""),"")} -> 8 | J19: {=IF(K19="Visa klasser",IFERROR(INDEX(ekipage!C:C, MATCH(1, (ekipage!N:N = A19) * (ISNUMBER(ekipage!P:P) = FALSE), 0)), "Ej individuell"),"Visar ej klasser")} -> Individuell junior 1* | K19: Visa klasser
A20: 200328 | B20: Olivia Nyberg | C20: Blå 3 | I20: {=IF(K20="Visa klasser",IFERROR(INDEX(ekipage!B:B,MATCH(1,(ekipage!N:N=A20)*(ISNUMBER(ekipage!P:P)=FALSE),0)),""),"")} -> 8 | J20: {=IF(K20="Visa klasser",IFERROR(INDEX(ekipage!C:C, MATCH(1, (ekipage!N:N = A20) * (ISNUMBER(ekipage!P:P) = FALSE), 0)), "Ej individuell"),"Visar ej klasser")} -> Individuell junior 1* | K20: Visa klasser
A21: 178209 | B21: Selma Åkesson | I21: {=IF(K21="Visa klasser",IFERROR(INDEX(ekipage!B:B,MATCH(1,(ekipage!N:N=A21)*(ISNUMBER(ekipage!P:P)=FALSE),0)),""),"")} | J21: {=IF(K21="Visa klasser",IFERROR(INDEX(ekipage!C:C, MATCH(1, (ekipage!N:N = A21) * (ISNUMBER(ekipage!P:P) = FALSE), 0)), "Ej individuell"),"Visar ej klasser")} -> Ej individuell | K21: Visa klasser
A22: 190842 | B22: Vera Bjarnemo | C22: Blå 9 | I22: {=IF(K22="Visa klasser",IFERROR(INDEX(ekipage!B:B,MATCH(1,(ekipage!N:N=A22)*(ISNUMBER(ekipage!P:P)=FALSE),0)),""),"")} -> 9 | J22: {=IF(K22="Visa klasser",IFERROR(INDEX(ekipage!C:C, MATCH(1, (ekipage!N:N = A22) * (ISNUMBER(ekipage!P:P) = FALSE), 0)), "Ej individuell"),"Visar ej klasser")} -> Individuell minior 1* | K22: Visa klasser
A23: 29744 | B23: Denice Sundberg | C23: Svart 10 | I23: {=IF(K23="Visa klasser",IFERROR(INDEX(ekipage!B:B,MATCH(1,(ekipage!N:N=A23)*(ISNUMBER(ekipage!P:P)=FALSE),0)),""),"")} -> 17 | J23: {=IF(K23="Visa klasser",IFERROR(INDEX(ekipage!C:C, MATCH(1, (ekipage!N:N = A23) * (ISNUMBER(ekipage!P:P) = FALSE), 0)), "Ej individuell"),"Visar ej klasser")} -> Lättklass, Individuell | K23: Visa klasser
A24: 163633 | B24: Julia Ekblom | C24: Svart 11 | I24: {=IF(K24="Visa klasser",IFERROR(INDEX(ekipage!B:B,MATCH(1,(ekipage!N:N=A24)*(ISNUMBER(ekipage!P:P)=FALSE),0)),""),"")} -> 17 | J24: {=IF(K24="Visa klasser",IFERROR(INDEX(ekipage!C:C, MATCH(1, (ekipage!N:N = A24) * (ISNUMBER(ekipage!P:P) = FALSE), 0)), "Ej individuell"),"Visar ej klasser")} -> Lättklass, Individuell | K24: Visa klasser
A25: 169428 | B25: Cecilia Viklund | C25: Svart 12 | I25: {=IF(K25="Visa klasser",IFERROR(INDEX(ekipage!B:B,MATCH(1,(ekipage!N:N=A25)*(ISNUMBER(ekipage!P:P)=FALSE),0)),""),"")} -> 17 | J25: {=IF(K25="Visa klasser",IFERROR(INDEX(ekipage!C:C, MATCH(1, (ekipage!N:N = A25) * (ISNUMBER(ekipage!P:P) = FALSE), 0)), "Ej individuell"),"Visar ej klasser")} -> Lättklass, Individuell | K25: Visa klasser
A26: 181877 | B26: Mollie Strandberg | C26: Svart 13 | I26: {=IF(K26="Visa klasser",IFERROR(INDEX(ekipage!B:B,MATCH(1,(ekipage!N:N=A26)*(ISNUMBER(ekipage!P:P)=FALSE),0)),""),"")} -> 17 | J26: {=IF(K26="Visa klasser",IFERROR(INDEX(ekipage!C:C, MATCH(1, (ekipage!N:N = A26) * (ISNUMBER(ekipage!P:P) = FALSE), 0)), "Ej individuell"),"Visar ej klasser")} -> Lättklass, Individuell | K26: Visa klasser
A27: 186749 | B27: Tyra Karlsson | C27: Svart 14 | I27: {=IF(K27="Visa klasser",IFERROR(INDEX(ekipage!B:B,MATCH(1,(ekipage!N:N=A27)*(ISNUMBER(ekipage!P:P)=FALSE),0)),""),"")} -> 17 | J27: {=IF(K27="Visa klasser",IFERROR(INDEX(ekipage!C:C, MATCH(1, (ekipage!N:N = A27) * (ISNUMBER(ekipage!P:P) = FALSE), 0)), "Ej individuell"),"Visar ej klasser")} -> Lättklass, Individuell | K27: Visa klasser
A28: 195019 | B28: Ebba Fasthamre | C28: Svart 15 | I28: {=IF(K28="Visa klasser",IFERROR(INDEX(ekipage!B:B,MATCH(1,(ekipage!N:N=A28)*(ISNUMBER(ekipage!P:P)=FALSE),0)),""),"")} -> 17 | J28: {=IF(K28="Visa klasser",IFERROR(INDEX(ekipage!C:C, MATCH(1, (ekipage!N:N = A28) * (ISNUMBER(ekipage!P:P) = FALSE), 0)), "Ej individuell"),"Visar ej klasser")} -> Lättklass, Individuell | K28: Visa klasser
A29: 195035 | B29: Haylie Rebane | C29: Svart 16 | I29: {=IF(K29="Visa klasser",IFERROR(INDEX(ekipage!B:B,MATCH(1,(ekipage!N:N=A29)*(ISNUMBER(ekipage!P:P)=FALSE),0)),""),"")} -> 17 | J29: {=IF(K29="Visa klasser",IFERROR(INDEX(ekipage!C:C, MATCH(1, (ekipage!N:N = A29) * (ISNUMBER(ekipage!P:P) = FALSE), 0)), "Ej individuell"),"Visar ej klasser")} -> Lättklass, Individuell | K29: Visa klasser
A30: 206243 | B30: Elsa Söderberg | C30: Svart 9 | I30: {=IF(K30="Visa klasser",IFERROR(INDEX(ekipage!B:B,MATCH(1,(ekipage!N:N=A30)*(ISNUMBER(ekipage!P:P)=FALSE),0)),""),"")} -> 17 | J30: {=IF(K30="Visa klasser",IFERROR(INDEX(ekipage!C:C, MATCH(1, (ekipage!N:N = A30) * (ISNUMBER(ekipage!P:P) = FALSE), 0)), "Ej individuell"),"Visar ej klasser")} -> Lättklass, Individuell | K30: Visa klasser
A31: 186646 | B31: Lilly Hedlund | C31: Blå 7 | I31: {=IF(K31="Visa klasser",IFERROR(INDEX(ekipage!B:B,MATCH(1,(ekipage!N:N=A31)*(ISNUMBER(ekipage!P:P)=FALSE),0)),""),"")} -> 18 | J31: {=IF(K31="Visa klasser",IFERROR(INDEX(ekipage!C:C, MATCH(1, (ekipage!N:N = A31) * (ISNUMBER(ekipage!P:P) = FALSE), 0)), "Ej individuell"),"Visar ej klasser")} -> Skrittklass, individuell | K31: Visa klasser
A32: 186751 | B32: Sofia Ekström | C32: Blå 8 | I32: {=IF(K32="Visa klasser",IFERROR(INDEX(ekipage!B:B,MATCH(1,(ekipage!N:N=A32)*(ISNUMBER(ekipage!P:P)=FALSE),0)),""),"")} -> 18 | J32: {=IF(K32="Visa klasser",IFERROR(INDEX(ekipage!C:C, MATCH(1, (ekipage!N:N = A32) * (ISNUMBER(ekipage!P:P) = FALSE), 0)), "Ej individuell"),"Visar ej klasser")} -> Skrittklass, individuell | K32: Visa klasser
A33: 186781 | B33: Filippa Olofsson | C33: Blå 10 | I33: {=IF(K33="Visa klasser",IFERROR(INDEX(ekipage!B:B,MATCH(1,(ekipage!N:N=A33)*(ISNUMBER(ekipage!P:P)=FALSE),0)),""),"")} -> 18 | J33: {=IF(K33="Visa klasser",IFERROR(INDEX(ekipage!C:C, MATCH(1, (ekipage!N:N = A33) * (ISNUMBER(ekipage!P:P) = FALSE), 0)), "Ej individuell"),"Visar ej klasser")} -> Skrittklass, individuell | K33: Visa klasser
... A43: 205893 | B43: Melina Vesterholm | C43: Vi 23 | I43: {=IF(K43="Visa klasser",IFERROR(INDEX(ekipage!B:B,MATCH(1,(ekipage!N:N=A43)*(ISNUMBER(ekipage!P:P)=FALSE),0)),""),"")} -> 18 | J43: {=IF(K43="Visa klasser",IFERROR(INDEX(ekipage!C:C, MATCH(1, (ekipage!N:N = A43) * (ISNUMBER(ekipage!P:P) = FALSE), 0)), "Ej individuell"),"Visar ej klasser")} -> Skrittklass, individuell | K43: Visa klasser
A44: 90 | B44: Elvira Androos | I44: {=IF(K44="Visa klasser",IFERROR(INDEX(ekipage!B:B,MATCH(1,(ekipage!N:N=A44)*(ISNUMBER(ekipage!P:P)=FALSE),0)),""),"")} | J44: {=IF(K44="Visa klasser",IFERROR(INDEX(ekipage!C:C, MATCH(1, (ekipage!N:N = A44) * (ISNUMBER(ekipage!P:P) = FALSE), 0)), "Ej individuell"),"Visar ej klasser")} -> Ej individuell | K44: Visa klasser
A45: 91 | B45: Selma Ouled El Housseine | I45: {=IF(K45="Visa klasser",IFERROR(INDEX(ekipage!B:B,MATCH(1,(ekipage!N:N=A45)*(ISNUMBER(ekipage!P:P)=FALSE),0)),""),"")} | J45: {=IF(K45="Visa klasser",IFERROR(INDEX(ekipage!C:C, MATCH(1, (ekipage!N:N = A45) * (ISNUMBER(ekipage!P:P) = FALSE), 0)), "Ej individuell"),"Visar ej klasser")} -> Ej individuell | K45: Visa klasser
A46: 92 | B46: Tilda Månsson | I46: {=IF(K46="Visa klasser",IFERROR(INDEX(ekipage!B:B,MATCH(1,(ekipage!N:N=A46)*(ISNUMBER(ekipage!P:P)=FALSE),0)),""),"")} | J46: {=IF(K46="Visa klasser",IFERROR(INDEX(ekipage!C:C, MATCH(1, (ekipage!N:N = A46) * (ISNUMBER(ekipage!P:P) = FALSE), 0)), "Ej individuell"),"Visar ej klasser")} -> Ej individuell | K46: Visa klasser
A47: 93 | B47: Signe Säfström | I47: {=IF(K47="Visa klasser",IFERROR(INDEX(ekipage!B:B,MATCH(1,(ekipage!N:N=A47)*(ISNUMBER(ekipage!P:P)=FALSE),0)),""),"")} | J47: {=IF(K47="Visa klasser",IFERROR(INDEX(ekipage!C:C, MATCH(1, (ekipage!N:N = A47) * (ISNUMBER(ekipage!P:P) = FALSE), 0)), "Ej individuell"),"Visar ej klasser")} -> Ej individuell | K47: Visa klasser
A48: 94 | B48: Mila Thulin | I48: {=IF(K48="Visa klasser",IFERROR(INDEX(ekipage!B:B,MATCH(1,(ekipage!N:N=A48)*(ISNUMBER(ekipage!P:P)=FALSE),0)),""),"")} | J48: {=IF(K48="Visa klasser",IFERROR(INDEX(ekipage!C:C, MATCH(1, (ekipage!N:N = A48) * (ISNUMBER(ekipage!P:P) = FALSE), 0)), "Ej individuell"),"Visar ej klasser")} -> Ej individuell | K48: Visa klasser
A49: 95 | B49: Felicia Söderman | I49: {=IF(K49="Visa klasser",IFERROR(INDEX(ekipage!B:B,MATCH(1,(ekipage!N:N=A49)*(ISNUMBER(ekipage!P:P)=FALSE),0)),""),"")} | J49: {=IF(K49="Visa klasser",IFERROR(INDEX(ekipage!C:C, MATCH(1, (ekipage!N:N = A49) * (ISNUMBER(ekipage!P:P) = FALSE), 0)), "Ej individuell"),"Visar ej klasser")} -> Ej individuell | K49: Visa klasser
...
